File: XRD analysis/data/P0142OP_2theta_15-115deg_83mins.ras
*RAS_DATA_START
*RAS_HEADER_START
*DISP_FMT_X "%.2f"
*DISP_FMT_Y "%.0f"
*DISP_FULLSCALE "1229363683.0151994000"
*DISP_LINE_COLOR "255.0000000000"
*DISP_LINE_STYLE "0.0000000000"
*DISP_LINE_WIDTH "0.2500000000"
*DISP_NOTE "Collected Data-2"
*DISP_OFFSET_Y "0.0000000000"
*DISP_PEAKSEARCH_UNIT_Y "cps"
*DISP_RANGE_BOTTOM "0.0100000000"
*DISP_RANGE_LEFT "0.2000000000"
*DISP_RANGE_LOGCUTOFF "0.0100000000"
*DISP_RANGE_RIGHT "115.0000000000"
*DISP_RANGE_TOP "1229363683.0151994000"
*DISP_SCALE_MODE_Y "2.0000000000"
*DISP_TAB_NAME "2-Theta/Omega"
*DISP_TITLE_Y "Intensity"
*DISP_UNIT_Y "cps"
*DISP_WINDOW_NAME "MSG_MACROENGINE"
*FILE_COMMENT " "
*FILE_MD5 ""
*FILE_MEMO " "
*FILE_OPERATOR "SmartLab"
*FILE_PART_ID "MEAS_KHP2_00061"
*FILE_SAMPLE "P0142OP"
*FILE_TYPE "RAS_RAW"
*FILE_USERGROUP "System Manager"
*FILE_VERSION "1.0000000000"
*HW_ATTACHMENT_ID "ATT0022"
*HW_ATTACHMENT_NAME "RxRy|RxRy"
*HW_COUNTER_ID-0 "CUT0021"
*HW_COUNTER_ID-1 "CUT0051"
*HW_COUNTER_ID-2 "CUT0020"
*HW_COUNTER_ID-3 "CSL0021"
*HW_COUNTER_ID-4 "CMC0021"
*HW_COUNTER_NAME-0 "SC-70|SC-70"
*HW_COUNTER_NAME-1 "HyPix 3000(H)|HyPix 3000(H)"
*HW_COUNTER_NAME-2 "None|None"
*HW_COUNTER_NAME-3 "BBM|BBM"
*HW_COUNTER_NAME-4 "検出器モノクロメータ|Detector monochromator"
*HW_COUNTER_SELECT_NAME "SC-70|SC-70"
*HW_ECP_HV "619.0000000000"
*HW_ECP_HV_UNIT "V"
*HW_GONIOMETER_ID "GON0024"
*HW_GONIOMETER_NAME "SmartLab(In-plane)|SmartLab(In-plane)"
*HW_GONIOMETER_RADIUS-0 "90.0"
*HW_GONIOMETER_RADIUS-1 "114.0"
*HW_GONIOMETER_RADIUS-2 "190.0"
*HW_GONIOMETER_RADIUS-3 "300.0"
*HW_GONIOMETER_RADIUS-4 "187.0"
*HW_GONIOMETER_RADIUS-5 "300.0"
*HW_GONIOMETER_RADIUS-6 "113.0"
*HW_GONIOMETER_RADIUS-7 "331.0"
*HW_I_OPT_ID-0 "CBO0021"
*HW_I_OPT_ID-1 "ICR0021"
*HW_I_OPT_ID-2 "ISL0021"
*HW_I_OPT_ID-3 "ISO0021"
*HW_I_OPT_ID-4 "IAD0021"
*HW_I_OPT_ID-5 "IPR0001"
*HW_I_OPT_NAME-0 "CBOユニット|CBO unit"
*HW_I_OPT_NAME-1 "標準入射光学ユニット|Standard incident optical unit"
*HW_I_OPT_NAME-2 "標準入射スリットボックス|Standard incident slit box"
*HW_I_OPT_NAME-3 "入射平行スリット|Incident parallel slit"
*HW_I_OPT_NAME-4 "長手制限スリット|Length limiting slit"
*HW_I_OPT_NAME-5 "None|None"
*HW_R_ATTENUATER_AUTOMODE "1"
*HW_R_OPT_ID-0 "RSS0021"
*HW_R_OPT_ID-1 "RCR0022"
*HW_R_OPT_ID-2 "RSO0021"
*HW_R_OPT_ID-3 "RRS0021"
*HW_R_OPT_ID-4 "ATN0021"
*HW_R_OPT_ID-5 "RFL0021"
*HW_R_OPT_ID-6 "RAD0021"
*HW_R_OPT_NAME-0 "標準受光スリットボックス1|Standard receiving slit box # 1"
*HW_R_OPT_NAME-1 "標準受光光学ユニット1|Standard receiving unit # 1"
*HW_R_OPT_NAME-2 "標準受光光学ユニット2|Standard receiving optical unit # 2"
*HW_R_OPT_NAME-3 "標準受光スリットボックス2|Standard receiving slit box # 2"
*HW_R_OPT_NAME-4 "標準アッテネータ|Standard Attenuator"
*HW_R_OPT_NAME-5 "Cu Kβ|Cu K-beta"
*HW_R_OPT_NAME-6 "調整用受光スリット|Alignment receiving slit"
*HW_SAMPLE_HOLDER_ID "SMP0021"
*HW_SAMPLE_HOLDER_NAME "χφZクレードル|Chi phi Z cradle"
*HW_XG_CURRENT_MAX "200"
*HW_XG_CURRENT_MIN "10"
*HW_XG_CURRENT_RESOLUTION "1"
*HW_XG_CURRENT_UNIT "mA"
*HW_XG_FOCUS "0.4mm x 8mm"
*HW_XG_FOCUS_TYPE "Normal"
*HW_XG_ID "1700"
*HW_XG_NAME "9kW 開放管(45kV 200mA ID:1700)|9kW Rotating anode(45kV 200mA ID:1700)"
*HW_XG_TARGET_ATOMIC_NUMBER "29.0000000000"
*HW_XG_TARGET_NAME "Cu"
*HW_XG_TYPE "Rota"
*HW_XG_VOLTAGE_MAX "45"
*HW_XG_VOLTAGE_MIN "20"
*HW_XG_VOLTAGE_RESOLUTION "1"
*HW_XG_VOLTAGE_UNIT "kV"
*HW_XG_WATT_MAX "9.00"
*HW_XG_WATT_UNIT "kW"
*HW_XG_WAVE_LENGTH_ALPHA1 "1.540593"
*HW_XG_WAVE_LENGTH_ALPHA2 "1.544414"
*HW_XG_WAVE_LENGTH_BETA "1.392250"
*MEAS_COND_AXIS_NAME-0 "Theta/2-Theta"
*MEAS_COND_AXIS_NAME-1 "2-Theta"
*MEAS_COND_AXIS_NAME-2 "Omega"
*MEAS_COND_AXIS_NAME-3 "Chi"
*MEAS_COND_AXIS_NAME-4 "Phi"
*MEAS_COND_AXIS_NAME-5 "Z"
*MEAS_COND_AXIS_NAME-6 "Rx"
*MEAS_COND_AXIS_NAME-7 "Ry"
*MEAS_COND_AXIS_NAME-8 "2-Theta/Omega"
*MEAS_COND_AXIS_NAME-9 "2-ThetaChi"
*MEAS_COND_AXIS_NAME-10 "2-ThetaChi/Phi"
*MEAS_COND_AXIS_NAME-11 "Alpha"
*MEAS_COND_AXIS_NAME-12 "Beta"
*MEAS_COND_AXIS_NAME-13 "Theta_s"
*MEAS_COND_AXIS_NAME-14 "Theta_d"
*MEAS_COND_AXIS_NAME-15 "Ts"
*MEAS_COND_AXIS_NAME-16 "CBO selection slit"
*MEAS_COND_AXIS_NAME-17 "M"
*MEAS_COND_AXIS_NAME-18 "Incident parallel slit"
*MEAS_COND_AXIS_NAME-19 "Incident slit"
*MEAS_COND_AXIS_NAME-20 ""
*MEAS_COND_AXIS_NAME-21 "Zs"
*MEAS_COND_AXIS_NAME-22 "Incident optical device"
*MEAS_COND_AXIS_NAME-23 "Omega_m"
*MEAS_COND_AXIS_NAME-24 "Length limiting slit"
*MEAS_COND_AXIS_NAME-25 "Center slit"
*MEAS_COND_AXIS_NAME-26 "Filter"
*MEAS_COND_AXIS_NAME-27 "Receiving slit # 1"
*MEAS_COND_AXIS_NAME-28 "Receiving slit # 2"
*MEAS_COND_AXIS_NAME-29 "Receiving optical device"
*MEAS_COND_AXIS_NAME-30 "Receiving parallel slit"
*MEAS_COND_AXIS_NAME-31 "Alignment receiving slit"
*MEAS_COND_AXIS_NAME-32 ""
*MEAS_COND_AXIS_NAME-33 ""
*MEAS_COND_AXIS_NAME-34 "Zd"
*MEAS_COND_AXIS_NAME-35 "Attenuator"
*MEAS_COND_AXIS_NAME-36 "Diffracted beam monochromator"
*MEAS_COND_AXIS_NAME-37 "Monochromator slit"
*MEAS_COND_AXIS_NAME-38 "2-ThetaB"
*MEAS_COND_AXIS_NAME-39 ""
*MEAS_COND_AXIS_NAME-40 ""
*MEAS_COND_AXIS_NAME-41 "Primary beam"
*MEAS_COND_AXIS_NAME_INTERNAL-0 "TwoThetaTheta"
*MEAS_COND_AXIS_NAME_INTERNAL-1 "TwoTheta"
*MEAS_COND_AXIS_NAME_INTERNAL-2 "Omega"
*MEAS_COND_AXIS_NAME_INTERNAL-3 "Chi"
*MEAS_COND_AXIS_NAME_INTERNAL-4 "Phi"
*MEAS_COND_AXIS_NAME_INTERNAL-5 "Z"
*MEAS_COND_AXIS_NAME_INTERNAL-6 "Rx"
*MEAS_COND_AXIS_NAME_INTERNAL-7 "Ry"
*MEAS_COND_AXIS_NAME_INTERNAL-8 "TwoThetaOmega"
*MEAS_COND_AXIS_NAME_INTERNAL-9 "TwoThetaChi"
*MEAS_COND_AXIS_NAME_INTERNAL-10 "TwoThetaChiPhi"
*MEAS_COND_AXIS_NAME_INTERNAL-11 "Alpha"
*MEAS_COND_AXIS_NAME_INTERNAL-12 "Beta"
*MEAS_COND_AXIS_NAME_INTERNAL-13 "ThetaS"
*MEAS_COND_AXIS_NAME_INTERNAL-14 "ThetaD"
*MEAS_COND_AXIS_NAME_INTERNAL-15 "Ts"
*MEAS_COND_AXIS_NAME_INTERNAL-16 "CBO"
*MEAS_COND_AXIS_NAME_INTERNAL-17 "CBO-M"
*MEAS_COND_AXIS_NAME_INTERNAL-18 "IncidentSollerSlit"
*MEAS_COND_AXIS_NAME_INTERNAL-19 "IncidentSlitBox"
*MEAS_COND_AXIS_NAME_INTERNAL-20 "IncidentSlitBox-_Axis"
*MEAS_COND_AXIS_NAME_INTERNAL-21 "Zs"
*MEAS_COND_AXIS_NAME_INTERNAL-22 "IncidentMonochromator"
*MEAS_COND_AXIS_NAME_INTERNAL-23 "IncidentMonochromator-OmegaM"
*MEAS_COND_AXIS_NAME_INTERNAL-24 "IncidentAxdSlit"
*MEAS_COND_AXIS_NAME_INTERNAL-25 "CenterSlit"
*MEAS_COND_AXIS_NAME_INTERNAL-26 "Filter"
*MEAS_COND_AXIS_NAME_INTERNAL-27 "ReceivingSlitBox1"
*MEAS_COND_AXIS_NAME_INTERNAL-28 "ReceivingSlitBox2"
*MEAS_COND_AXIS_NAME_INTERNAL-29 "ReceivingOptics"
*MEAS_COND_AXIS_NAME_INTERNAL-30 "ReceivingSollerSlit"
*MEAS_COND_AXIS_NAME_INTERNAL-31 "ReceivingAxdSlit"
*MEAS_COND_AXIS_NAME_INTERNAL-32 "ReceivingSlitBox1-_Axis"
*MEAS_COND_AXIS_NAME_INTERNAL-33 "ReceivingSlitBox2-_Axis"
*MEAS_COND_AXIS_NAME_INTERNAL-34 "ReceivingSlitBox2-Zd"
*MEAS_COND_AXIS_NAME_INTERNAL-35 "Attenuator"
*MEAS_COND_AXIS_NAME_INTERNAL-36 "CounterMonochromator"
*MEAS_COND_AXIS_NAME_INTERNAL-37 "CounterSlit"
*MEAS_COND_AXIS_NAME_INTERNAL-38 "TwoThetaB"
*MEAS_COND_AXIS_NAME_INTERNAL-39 "AlphaR"
*MEAS_COND_AXIS_NAME_INTERNAL-40 "BetaR"
*MEAS_COND_AXIS_NAME_INTERNAL-41 "IncidentPrimary"
*MEAS_COND_AXIS_NAME_MAGICNO-0 "83951616.0000000000"
*MEAS_COND_AXIS_NAME_MAGICNO-1 "268632064.0000000000"
*MEAS_COND_AXIS_NAME_MAGICNO-2 "268500992.0000000000"
*MEAS_COND_AXIS_NAME_MAGICNO-3 "268500992.0000000000"
*MEAS_COND_AXIS_NAME_MAGICNO-4 "268500992.0000000000"
*MEAS_COND_AXIS_NAME_MAGICNO-5 "285278208.0000000000"
*MEAS_COND_AXIS_NAME_MAGICNO-6 "285278208.0000000000"
*MEAS_COND_AXIS_NAME_MAGICNO-7 "285278208.0000000000"
*MEAS_COND_AXIS_NAME_MAGICNO-8 "83951616.0000000000"
*MEAS_COND_AXIS_NAME_MAGICNO-9 "268632064.0000000000"
*MEAS_COND_AXIS_NAME_MAGICNO-10 "83951616.0000000000"
*MEAS_COND_AXIS_NAME_MAGICNO-11 "17039360.0000000000"
*MEAS_COND_AXIS_NAME_MAGICNO-12 "17039360.0000000000"
*MEAS_COND_AXIS_NAME_MAGICNO-13 "131072.0000000000"
*MEAS_COND_AXIS_NAME_MAGICNO-14 "131072.0000000000"
*MEAS_COND_AXIS_NAME_MAGICNO-15 "318898176.0000000000"
*MEAS_COND_AXIS_NAME_MAGICNO-16 "20971521.0000000000"
*MEAS_COND_AXIS_NAME_MAGICNO-17 "285343744.0000000000"
*MEAS_COND_AXIS_NAME_MAGICNO-18 "20971521.0000000000"
*MEAS_COND_AXIS_NAME_MAGICNO-19 "22020097.0000000000"
*MEAS_COND_AXIS_NAME_MAGICNO-20 "25165824.0000000000"
*MEAS_COND_AXIS_NAME_MAGICNO-21 "318898176.0000000000"
*MEAS_COND_AXIS_NAME_MAGICNO-22 "20971521.0000000000"
*MEAS_COND_AXIS_NAME_MAGICNO-23 "285343744.0000000000"
*MEAS_COND_AXIS_NAME_MAGICNO-24 "20971521.0000000000"
*MEAS_COND_AXIS_NAME_MAGICNO-25 "20971521.0000000000"
*MEAS_COND_AXIS_NAME_MAGICNO-26 "20971521.0000000000"
*MEAS_COND_AXIS_NAME_MAGICNO-27 "23068673.0000000000"
*MEAS_COND_AXIS_NAME_MAGICNO-28 "23068673.0000000000"
*MEAS_COND_AXIS_NAME_MAGICNO-29 "20971521.0000000000"
*MEAS_COND_AXIS_NAME_MAGICNO-30 "20971521.0000000000"
*MEAS_COND_AXIS_NAME_MAGICNO-31 "20971521.0000000000"
*MEAS_COND_AXIS_NAME_MAGICNO-32 "25165824.0000000000"
*MEAS_COND_AXIS_NAME_MAGICNO-33 "25165824.0000000000"
*MEAS_COND_AXIS_NAME_MAGICNO-34 "285343744.0000000000"
*MEAS_COND_AXIS_NAME_MAGICNO-35 "17301505.0000000000"
*MEAS_COND_AXIS_NAME_MAGICNO-36 "20971521.0000000000"
*MEAS_COND_AXIS_NAME_MAGICNO-37 "20971521.0000000000"
*MEAS_COND_AXIS_NAME_MAGICNO-38 "17039360.0000000000"
*MEAS_COND_AXIS_NAME_MAGICNO-39 "8388608.0000000000"
*MEAS_COND_AXIS_NAME_MAGICNO-40 "8388608.0000000000"
*MEAS_COND_AXIS_NAME_MAGICNO-41 "20971521.0000000000"
*MEAS_COND_AXIS_OFFSET-0 "-"
*MEAS_COND_AXIS_OFFSET-1 "0.9505000000"
*MEAS_COND_AXIS_OFFSET-2 "0.9585000000"
*MEAS_COND_AXIS_OFFSET-3 "0.0000000000"
*MEAS_COND_AXIS_OFFSET-4 "0.0000000000"
*MEAS_COND_AXIS_OFFSET-5 "-"
*MEAS_COND_AXIS_OFFSET-6 "-"
*MEAS_COND_AXIS_OFFSET-7 "-"
*MEAS_COND_AXIS_OFFSET-8 "-"
*MEAS_COND_AXIS_OFFSET-9 "0.0785000000"
*MEAS_COND_AXIS_OFFSET-10 "-"
*MEAS_COND_AXIS_OFFSET-11 "-"
*MEAS_COND_AXIS_OFFSET-12 "-"
*MEAS_COND_AXIS_OFFSET-13 "0.9585000000"
*MEAS_COND_AXIS_OFFSET-14 "-0.0080000000"
*MEAS_COND_AXIS_OFFSET-15 "-"
*MEAS_COND_AXIS_OFFSET-16 "-"
*MEAS_COND_AXIS_OFFSET-17 "-"
*MEAS_COND_AXIS_OFFSET-18 "-"
*MEAS_COND_AXIS_OFFSET-19 "-"
*MEAS_COND_AXIS_OFFSET-20 "-"
*MEAS_COND_AXIS_OFFSET-21 "-"
*MEAS_COND_AXIS_OFFSET-22 "-"
*MEAS_COND_AXIS_OFFSET-23 "-"
*MEAS_COND_AXIS_OFFSET-24 "-"
*MEAS_COND_AXIS_OFFSET-25 "-"
*MEAS_COND_AXIS_OFFSET-26 "-"
*MEAS_COND_AXIS_OFFSET-27 "-"
*MEAS_COND_AXIS_OFFSET-28 "-"
*MEAS_COND_AXIS_OFFSET-29 "-"
*MEAS_COND_AXIS_OFFSET-30 "-"
*MEAS_COND_AXIS_OFFSET-31 "-"
*MEAS_COND_AXIS_OFFSET-32 "-"
*MEAS_COND_AXIS_OFFSET-33 "-"
*MEAS_COND_AXIS_OFFSET-34 "-"
*MEAS_COND_AXIS_OFFSET-35 "-"
*MEAS_COND_AXIS_OFFSET-36 "-"
*MEAS_COND_AXIS_OFFSET-37 "-"
*MEAS_COND_AXIS_OFFSET-38 "-"
*MEAS_COND_AXIS_OFFSET-39 "0.0000000000"
*MEAS_COND_AXIS_OFFSET-40 "0.0000000000"
*MEAS_COND_AXIS_OFFSET-41 "-"
*MEAS_COND_AXIS_POSITION-0 "14.9950000000"
*MEAS_COND_AXIS_POSITION-1 "14.9950000000"
*MEAS_COND_AXIS_POSITION-2 "7.4974000000"
*MEAS_COND_AXIS_POSITION-3 "-0.0560000000"
*MEAS_COND_AXIS_POSITION-4 "0.0000000000"
*MEAS_COND_AXIS_POSITION-5 "-0.6377000000"
*MEAS_COND_AXIS_POSITION-6 "0.0000000000"
*MEAS_COND_AXIS_POSITION-7 "0.0000000000"
*MEAS_COND_AXIS_POSITION-8 "14.9950000000"
*MEAS_COND_AXIS_POSITION-9 "0.0000000000"
*MEAS_COND_AXIS_POSITION-10 "0.0000000000"
*MEAS_COND_AXIS_POSITION-11 "89.7000000000"
*MEAS_COND_AXIS_POSITION-12 "-0.0380000000"
*MEAS_COND_AXIS_POSITION-13 "7.4974000000"
*MEAS_COND_AXIS_POSITION-14 "7.4976000000"
*MEAS_COND_AXIS_POSITION-15 "-6.4093100000"
*MEAS_COND_AXIS_POSITION-16 "PB"
*MEAS_COND_AXIS_POSITION-17 "0.0000000000"
*MEAS_COND_AXIS_POSITION-18 "Soller_slit_open_s"
*MEAS_COND_AXIS_POSITION-19 "1.000mm"
*MEAS_COND_AXIS_POSITION-20 "1.0000000000"
*MEAS_COND_AXIS_POSITION-21 "-1.7578100000"
*MEAS_COND_AXIS_POSITION-22 "Ge(220)x2"
*MEAS_COND_AXIS_POSITION-23 "0.0000000000"
*MEAS_COND_AXIS_POSITION-24 "2.0mm"
*MEAS_COND_AXIS_POSITION-25 "None"
*MEAS_COND_AXIS_POSITION-26 "None"
*MEAS_COND_AXIS_POSITION-27 "1.000mm"
*MEAS_COND_AXIS_POSITION-28 "1.000mm"
*MEAS_COND_AXIS_POSITION-29 "PSA_open"
*MEAS_COND_AXIS_POSITION-30 "Soller_slit_5.0deg"
*MEAS_COND_AXIS_POSITION-31 "None"
*MEAS_COND_AXIS_POSITION-32 "1.0000000000"
*MEAS_COND_AXIS_POSITION-33 "1.0000000000"
*MEAS_COND_AXIS_POSITION-34 "0.2150000000"
*MEAS_COND_AXIS_POSITION-35 "1/10000"
*MEAS_COND_AXIS_POSITION-36 "None"
*MEAS_COND_AXIS_POSITION-37 "None"
*MEAS_COND_AXIS_POSITION-38 "14.9950000000"
*MEAS_COND_AXIS_POSITION-39 "0.0580000000"
*MEAS_COND_AXIS_POSITION-40 "0.0000000000"
*MEAS_COND_AXIS_POSITION-41 "None"
*MEAS_COND_AXIS_UNIT-0 "deg"
*MEAS_COND_AXIS_UNIT-1 "deg"
*MEAS_COND_AXIS_UNIT-2 "deg"
*MEAS_COND_AXIS_UNIT-3 "deg"
*MEAS_COND_AXIS_UNIT-4 "deg"
*MEAS_COND_AXIS_UNIT-5 "mm"
*MEAS_COND_AXIS_UNIT-6 "deg"
*MEAS_COND_AXIS_UNIT-7 "deg"
*MEAS_COND_AXIS_UNIT-8 "deg"
*MEAS_COND_AXIS_UNIT-9 "deg"
*MEAS_COND_AXIS_UNIT-10 "deg"
*MEAS_COND_AXIS_UNIT-11 "deg"
*MEAS_COND_AXIS_UNIT-12 "deg"
*MEAS_COND_AXIS_UNIT-13 "deg"
*MEAS_COND_AXIS_UNIT-14 "deg"
*MEAS_COND_AXIS_UNIT-15 "mm"
*MEAS_COND_AXIS_UNIT-16 ""
*MEAS_COND_AXIS_UNIT-17 "pulse"
*MEAS_COND_AXIS_UNIT-18 ""
*MEAS_COND_AXIS_UNIT-19 ""
*MEAS_COND_AXIS_UNIT-20 "mm"
*MEAS_COND_AXIS_UNIT-21 "mm"
*MEAS_COND_AXIS_UNIT-22 ""
*MEAS_COND_AXIS_UNIT-23 "pulse"
*MEAS_COND_AXIS_UNIT-24 ""
*MEAS_COND_AXIS_UNIT-25 ""
*MEAS_COND_AXIS_UNIT-26 ""
*MEAS_COND_AXIS_UNIT-27 ""
*MEAS_COND_AXIS_UNIT-28 ""
*MEAS_COND_AXIS_UNIT-29 ""
*MEAS_COND_AXIS_UNIT-30 ""
*MEAS_COND_AXIS_UNIT-31 ""
*MEAS_COND_AXIS_UNIT-32 "mm"
*MEAS_COND_AXIS_UNIT-33 "mm"
*MEAS_COND_AXIS_UNIT-34 "mm"
*MEAS_COND_AXIS_UNIT-35 ""
*MEAS_COND_AXIS_UNIT-36 ""
*MEAS_COND_AXIS_UNIT-37 ""
*MEAS_COND_AXIS_UNIT-38 "deg"
*MEAS_COND_AXIS_UNIT-39 "deg"
*MEAS_COND_AXIS_UNIT-40 "deg"
*MEAS_COND_AXIS_UNIT-41 ""
*MEAS_COND_COUNTER_CNTLOSS_CORR "1.0000000000"
*MEAS_COND_COUNTER_PHABASE "577.5000000000"
*MEAS_COND_COUNTER_PHAWINDOW "831.2500000000"
*MEAS_COND_COUNTER_PHA_UNIT "mV"
*MEAS_COND_COUNTER_TAUDIFF "0.2268340000"
*MEAS_COND_COUNTER_TAUINT "0.8841030000"
*MEAS_COND_IRRADIATION_MODE "OFF"
*MEAS_COND_IRRADIATION_WIDTH ""
*MEAS_COND_OPT_ATTR "High resolution parallel beam Ge(220)x2/RS"
*MEAS_COND_OPT_NAME "@High resolution PB-Ge(220)x2"
*MEAS_COND_UNSYMMETRIC_MODE "OFF"
*MEAS_COND_XG_CURRENT "200.0000000000"
*MEAS_COND_XG_VOLTAGE "45.0000000000"
*MEAS_COND_XG_WAVE_TYPE "Ka1"
*MEAS_DATA_COUNT "10001.0000000000"
*MEAS_SCAN_AXIS_X "2-Theta/Omega"
*MEAS_SCAN_AXIS_X_INTERNAL "TwoThetaOmega"
*MEAS_SCAN_END_TIME "10/21/20 12:45:19"
*MEAS_SCAN_MODE "CONTINUOUS"
*MEAS_SCAN_MONITOR "0"
*MEAS_SCAN_RESOLUTION_X "0.0002"
*MEAS_SCAN_SPEED "1.200000"
*MEAS_SCAN_SPEED_UNIT "deg/min"
*MEAS_SCAN_SPEED_USER "1.2000"
*MEAS_SCAN_START "15.0000000000"
*MEAS_SCAN_START_TIME "10/21/20 11:18:58"
*MEAS_SCAN_STEP "0.0100000000"
*MEAS_SCAN_STOP "115.0000000000"
*MEAS_SCAN_UNIT_X "deg"
*MEAS_SCAN_UNIT_Y "counts"
*RAS_HEADER_END
*RAS_INT_START
15.0000 18.0000 1.0000
15.0700 11.0000 1.0000
15.1400 19.0000 1.0000
15.2100 16.0000 1.0000
15.2800 16.0000 1.0000
15.3500 15.0000 1.0000
15.4200 17.0000 1.0000
15.4900 16.0000 1.0000
15.5600 11.0000 1.0000
15.6300 13.0000 1.0000
15.7000 25.0000 1.0000
15.7700 23.0000 1.0000
15.8400 11.0000 1.0000
15.9100 16.0000 1.0000
15.9800 17.0000 1.0000
16.0500 13.0000 1.0000
16.1200 17.0000 1.0000
16.1900 18.0000 1.0000
16.2600 16.0000 1.0000
16.3300 15.0000 1.0000
16.4000 14.0000 1.0000
16.4700 13.0000 1.0000
16.5400 18.0000 1.0000
16.6100 13.0000 1.0000
16.6800 21.0000 1.0000
16.7500 14.0000 1.0000
16.8200 19.0000 1.0000
16.8900 18.0000 1.0000
16.9600 15.0000 1.0000
17.0300 23.0000 1.0000
17.1000 17.0000 1.0000
17.1700 13.0000 1.0000
17.2400 37.0000 1.0000
17.3100 22.0000 1.0000
17.3800 18.0000 1.0000
17.4500 25.0000 1.0000
17.5200 14.0000 1.0000
17.5900 28.0000 1.0000
17.6600 29.0000 1.0000
17.7300 27.0000 1.0000
17.8000 28.0000 1.0000
17.8700 33.0000 1.0000
17.9400 24.0000 1.0000
18.0100 37.0000 1.0000
18.0800 31.0000 1.0000
18.1500 34.0000 1.0000
18.2200 23.0000 1.0000
18.2900 33.0000 1.0000
18.3600 39.0000 1.0000
18.4300 31.0000 1.0000
18.5000 41.0000 1.0000
18.5700 34.0000 1.0000
18.6400 31.0000 1.0000
18.7100 23.0000 1.0000
18.7800 35.0000 1.0000
18.8500 32.0000 1.0000
18.9200 33.0000 1.0000
18.9900 53.0000 1.0000
19.0600 52.0000 1.0000
19.1300 55.0000 1.0000
19.2000 58.0000 1.0000
19.2700 64.0000 1.0000
19.3400 76.0000 1.0000
19.4100 77.0000 1.0000
19.4800 68.0000 1.0000
19.5500 99.0000 1.0000
19.6200 70.0000 1.0000
19.6900 80.0000 1.0000
19.7600 97.0000 1.0000
19.8300 69.0000 1.0000
19.9000 90.0000 1.0000
19.9700 112.0000 1.0000
20.0400 100.0000 1.0000
20.1100 119.0000 1.0000
20.1800 167.0000 1.0000
20.2500 180.0000 1.0000
20.3200 135.0000 1.0000
20.3900 259.0000 1.0000
20.4600 341.0000 1.0000
20.5300 155.0000 1.0000
20.6000 434.0000 1.0000
20.6700 491.0000 1.0000
20.7400 217.0000 1.0000
20.8100 718.0000 1.0000
20.8800 823.0000 1.0000
20.9500 277.0000 1.0000
21.0200 1045.0000 1.0000
21.0900 1299.0000 1.0000
21.1600 405.0000 1.0000
21.2300 1692.0000 1.0000
21.3000 3025.0000 1.0000
21.3700 1089.0000 1.0000
21.4400 3880.0000 1.0000
21.5100 10467.0000 1.0000
21.5800 6122.0000 1.0000
21.6500 23559.0000 1.0000
21.7200 2677.0000 43.9397
21.7900 5302.0000 43.9397
21.8600 5398.0000 43.9397
21.9300 2777.0000 43.9397
22.0000 28448.0000 1.0000
22.0700 8263.0000 1.0000
22.1400 11750.0000 1.0000
22.2100 5064.0000 1.0000
22.2800 1830.0000 1.0000
22.3500 4589.0000 1.0000
22.4200 3126.0000 1.0000
22.4900 1220.0000 1.0000
22.5600 3060.0000 1.0000
22.6300 4200.0000 1.0000
22.7000 28794.0000 1.0000
22.7700 33154.0000 43.9397
22.8400 5250.0000 1.0000
22.9100 2190.0000 1.0000
22.9800 2477.0000 1.0000
23.0500 1430.0000 1.0000
23.1200 1148.0000 1.0000
23.1900 1423.0000 1.0000
23.2600 853.0000 1.0000
23.3300 728.0000 1.0000
23.4000 849.0000 1.0000
23.4700 445.0000 1.0000
23.5400 380.0000 1.0000
23.6100 368.0000 1.0000
23.6800 198.0000 1.0000
23.7500 162.0000 1.0000
23.8200 157.0000 1.0000
23.8900 64.0000 1.0000
23.9600 71.0000 1.0000
24.0300 37.0000 1.0000
24.1000 55.0000 1.0000
24.1700 50.0000 1.0000
24.2400 57.0000 1.0000
24.3100 61.0000 1.0000
24.3800 67.0000 1.0000
24.4500 65.0000 1.0000
24.5200 69.0000 1.0000
24.5900 49.0000 1.0000
24.6600 60.0000 1.0000
24.7300 58.0000 1.0000
24.8000 46.0000 1.0000
24.8700 38.0000 1.0000
24.9400 29.0000 1.0000
25.0100 28.0000 1.0000
25.0800 33.0000 1.0000
25.1500 23.0000 1.0000
25.2200 22.0000 1.0000
25.2900 17.0000 1.0000
25.3600 21.0000 1.0000
25.4300 19.0000 1.0000
25.5000 21.0000 1.0000
25.5700 19.0000 1.0000
25.6400 24.0000 1.0000
25.7100 32.0000 1.0000
25.7800 23.0000 1.0000
25.8500 26.0000 1.0000
25.9200 25.0000 1.0000
25.9900 21.0000 1.0000
26.0600 28.0000 1.0000
26.1300 23.0000 1.0000
26.2000 26.0000 1.0000
26.2700 13.0000 1.0000
26.3400 18.0000 1.0000
26.4100 14.0000 1.0000
26.4800 14.0000 1.0000
26.5500 7.0000 1.0000
26.6200 14.0000 1.0000
26.6900 12.0000 1.0000
26.7600 16.0000 1.0000
26.8300 13.0000 1.0000
26.9000 13.0000 1.0000
26.9700 13.0000 1.0000
27.0400 15.0000 1.0000
27.1100 16.0000 1.0000
27.1800 21.0000 1.0000
27.2500 12.0000 1.0000
27.3200 13.0000 1.0000
27.3900 24.0000 1.0000
27.4600 11.0000 1.0000
27.5300 17.0000 1.0000
27.6000 12.0000 1.0000
27.6700 9.0000 1.0000
27.7400 5.0000 1.0000
27.8100 12.0000 1.0000
27.8800 16.0000 1.0000
27.9500 10.0000 1.0000
28.0200 15.0000 1.0000
28.0900 11.0000 1.0000
28.1600 11.0000 1.0000
28.2300 16.0000 1.0000
28.3000 14.0000 1.0000
28.3700 10.0000 1.0000
28.4400 8.0000 1.0000
28.5100 13.0000 1.0000
28.5800 12.0000 1.0000
28.6500 12.0000 1.0000
28.7200 9.0000 1.0000
28.7900 16.0000 1.0000
28.8600 10.0000 1.0000
28.9300 11.0000 1.0000
29.0000 15.0000 1.0000
29.0700 8.0000 1.0000
29.1400 19.0000 1.0000
29.2100 12.0000 1.0000
29.2800 8.0000 1.0000
29.3500 13.0000 1.0000
29.4200 10.0000 1.0000
29.4900 11.0000 1.0000
29.5600 10.0000 1.0000
29.6300 9.0000 1.0000
29.7000 15.0000 1.0000
29.7700 18.0000 1.0000
29.8400 14.0000 1.0000
29.9100 10.0000 1.0000
29.9800 16.0000 1.0000
30.0500 10.0000 1.0000
30.1200 4.0000 1.0000
30.1900 16.0000 1.0000
30.2600 10.0000 1.0000
30.3300 10.0000 1.0000
30.4000 16.0000 1.0000
30.4700 2.0000 1.0000
30.5400 13.0000 1.0000
30.6100 9.0000 1.0000
30.6800 6.0000 1.0000
30.7500 8.0000 1.0000
30.8200 5.0000 1.0000
30.8900 11.0000 1.0000
30.9600 4.0000 1.0000
31.0300 14.0000 1.0000
31.1000 11.0000 1.0000
31.1700 11.0000 1.0000
31.2400 8.0000 1.0000
31.3100 13.0000 1.0000
31.3800 11.0000 1.0000
31.4500 8.0000 1.0000
31.5200 11.0000 1.0000
31.5900 7.0000 1.0000
31.6600 12.0000 1.0000
31.7300 15.0000 1.0000
31.8000 11.0000 1.0000
31.8700 11.0000 1.0000
31.9400 15.0000 1.0000
32.0100 16.0000 1.0000
32.0800 12.0000 1.0000
32.1500 15.0000 1.0000
32.2200 12.0000 1.0000
32.2900 10.0000 1.0000
32.3600 12.0000 1.0000
32.4300 12.0000 1.0000
32.5000 6.0000 1.0000
32.5700 12.0000 1.0000
32.6400 9.0000 1.0000
32.7100 16.0000 1.0000
32.7800 13.0000 1.0000
32.8500 13.0000 1.0000
32.9200 13.0000 1.0000
32.9900 12.0000 1.0000
33.0600 9.0000 1.0000
33.1300 17.0000 1.0000
33.2000 5.0000 1.0000
33.2700 11.0000 1.0000
33.3400 10.0000 1.0000
33.4100 11.0000 1.0000
33.4800 15.0000 1.0000
33.5500 7.0000 1.0000
33.6200 15.0000 1.0000
33.6900 12.0000 1.0000
33.7600 10.0000 1.0000
33.8300 15.0000 1.0000
33.9000 19.0000 1.0000
33.9700 16.0000 1.0000
34.0400 12.0000 1.0000
34.1100 9.0000 1.0000
34.1800 9.0000 1.0000
34.2500 10.0000 1.0000
34.3200 9.0000 1.0000
34.3900 19.0000 1.0000
34.4600 11.0000 1.0000
34.5300 18.0000 1.0000
34.6000 7.0000 1.0000
34.6700 12.0000 1.0000
34.7400 11.0000 1.0000
34.8100 8.0000 1.0000
34.8800 13.0000 1.0000
34.9500 17.0000 1.0000
35.0200 9.0000 1.0000
35.0900 8.0000 1.0000
35.1600 19.0000 1.0000
35.2300 7.0000 1.0000
35.3000 5.0000 1.0000
35.3700 19.0000 1.0000
35.4400 10.0000 1.0000
35.5100 8.0000 1.0000
35.5800 10.0000 1.0000
35.6500 10.0000 1.0000
35.7200 16.0000 1.0000
35.7900 13.0000 1.0000
35.8600 22.0000 1.0000
35.9300 11.0000 1.0000
36.0000 10.0000 1.0000
36.0700 15.0000 1.0000
36.1400 16.0000 1.0000
36.2100 7.0000 1.0000
36.2800 13.0000 1.0000
36.3500 12.0000 1.0000
36.4200 8.0000 1.0000
36.4900 18.0000 1.0000
36.5600 9.0000 1.0000
36.6300 15.0000 1.0000
36.7000 10.0000 1.0000
36.7700 9.0000 1.0000
36.8400 16.0000 1.0000
36.9100 10.0000 1.0000
36.9800 8.0000 1.0000
37.0500 15.0000 1.0000
37.1200 14.0000 1.0000
37.1900 11.0000 1.0000
37.2600 13.0000 1.0000
37.3300 18.0000 1.0000
37.4000 25.0000 1.0000
37.4700 9.0000 1.0000
37.5400 12.0000 1.0000
37.6100 13.0000 1.0000
37.6800 12.0000 1.0000
37.7500 14.0000 1.0000
37.8200 11.0000 1.0000
37.8900 19.0000 1.0000
37.9600 14.0000 1.0000
38.0300 17.0000 1.0000
38.1000 22.0000 1.0000
38.1700 9.0000 1.0000
38.2400 16.0000 1.0000
38.3100 12.0000 1.0000
38.3800 25.0000 1.0000
38.4500 16.0000 1.0000
38.5200 20.0000 1.0000
38.5900 22.0000 1.0000
38.6600 20.0000 1.0000
38.7300 13.0000 1.0000
38.8000 13.0000 1.0000
38.8700 21.0000 1.0000
38.9400 26.0000 1.0000
39.0100 11.0000 1.0000
39.0800 6.0000 1.0000
39.1500 15.0000 1.0000
39.2200 20.0000 1.0000
39.2900 20.0000 1.0000
39.3600 11.0000 1.0000
39.4300 15.0000 1.0000
39.5000 15.0000 1.0000
39.5700 23.0000 1.0000
39.6400 22.0000 1.0000
39.7100 14.0000 1.0000
39.7800 14.0000 1.0000
39.8500 19.0000 1.0000
39.9200 27.0000 1.0000
39.9900 28.0000 1.0000
40.0600 15.0000 1.0000
40.1300 18.0000 1.0000
40.2000 21.0000 1.0000
40.2700 26.0000 1.0000
40.3400 14.0000 1.0000
40.4100 21.0000 1.0000
40.4800 18.0000 1.0000
40.5500 27.0000 1.0000
40.6200 27.0000 1.0000
40.6900 25.0000 1.0000
40.7600 27.0000 1.0000
40.8300 27.0000 1.0000
40.9000 25.0000 1.0000
40.9700 19.0000 1.0000
41.0400 39.0000 1.0000
41.1100 24.0000 1.0000
41.1800 29.0000 1.0000
41.2500 32.0000 1.0000
41.3200 31.0000 1.0000
41.3900 35.0000 1.0000
41.4600 48.0000 1.0000
41.5300 35.0000 1.0000
41.6000 54.0000 1.0000
41.6700 47.0000 1.0000
41.7400 41.0000 1.0000
41.8100 46.0000 1.0000
41.8800 47.0000 1.0000
41.9500 44.0000 1.0000
42.0200 55.0000 1.0000
42.0900 39.0000 1.0000
42.1600 53.0000 1.0000
42.2300 51.0000 1.0000
42.3000 61.0000 1.0000
42.3700 57.0000 1.0000
42.4400 53.0000 1.0000
42.5100 59.0000 1.0000
42.5800 82.0000 1.0000
42.6500 61.0000 1.0000
42.7200 88.0000 1.0000
42.7900 110.0000 1.0000
42.8600 79.0000 1.0000
42.9300 103.0000 1.0000
43.0000 135.0000 1.0000
43.0700 103.0000 1.0000
43.1400 142.0000 1.0000
43.2100 204.0000 1.0000
43.2800 177.0000 1.0000
43.3500 209.0000 1.0000
43.4200 339.0000 1.0000
43.4900 286.0000 1.0000
43.5600 286.0000 1.0000
43.6300 496.0000 1.0000
43.7000 531.0000 1.0000
43.7700 493.0000 1.0000
43.8400 854.0000 1.0000
43.9100 1430.0000 1.0000
43.9800 1316.0000 1.0000
44.0500 2259.0000 1.0000
44.1200 5020.0000 1.0000
44.1900 6545.0000 1.0000
44.2600 11548.0000 1.0000
44.3300 35351.0000 1.0000
44.4000 77567.0000 1.0000
44.4700 2326.0000 43.9397
44.5400 1871.0000 43.9397
44.6100 46077.0000 1.0000
44.6800 19078.0000 1.0000
44.7500 11074.0000 1.0000
44.8200 8047.0000 1.0000
44.8900 4332.0000 1.0000
44.9600 2487.0000 1.0000
45.0300 2684.0000 1.0000
45.1000 2132.0000 1.0000
45.1700 1603.0000 1.0000
45.2400 1798.0000 1.0000
45.3100 1726.0000 1.0000
45.3800 1197.0000 1.0000
45.4500 1238.0000 1.0000
45.5200 1472.0000 1.0000
45.5900 1276.0000 1.0000
45.6600 1142.0000 1.0000
45.7300 1150.0000 1.0000
45.8000 833.0000 1.0000
45.8700 607.0000 1.0000
45.9400 648.0000 1.0000
46.0100 504.0000 1.0000
46.0800 304.0000 1.0000
46.1500 310.0000 1.0000
46.2200 415.0000 1.0000
46.2900 1730.0000 1.0000
46.3600 16729.0000 1.0000
46.4300 2259.0000 43.9397
46.5000 3853.9998 650.1090
46.5700 49807.0000 1.0000
46.6400 13705.0000 1.0000
46.7100 7262.0000 1.0000
46.7800 5094.0000 1.0000
46.8500 4094.0000 1.0000
46.9200 3382.0000 1.0000
46.9900 2767.0000 1.0000
47.0600 2575.0000 1.0000
47.1300 2118.0000 1.0000
47.2000 1822.0000 1.0000
47.2700 1770.0000 1.0000
47.3400 1477.0000 1.0000
47.4100 1166.0000 1.0000
47.4800 1079.0000 1.0000
47.5500 947.0000 1.0000
47.6200 831.0000 1.0000
47.6900 712.0000 1.0000
47.7600 571.0000 1.0000
47.8300 423.0000 1.0000
47.9000 344.0000 1.0000
47.9700 293.0000 1.0000
48.0400 211.0000 1.0000
48.1100 151.0000 1.0000
48.1800 124.0000 1.0000
48.2500 95.0000 1.0000
48.3200 41.0000 1.0000
48.3900 37.0000 1.0000
48.4600 30.0000 1.0000
48.5300 12.0000 1.0000
48.6000 20.0000 1.0000
48.6700 13.0000 1.0000
48.7400 14.0000 1.0000
48.8100 23.0000 1.0000
48.8800 13.0000 1.0000
48.9500 23.0000 1.0000
49.0200 26.0000 1.0000
49.0900 27.0000 1.0000
49.1600 22.0000 1.0000
49.2300 27.0000 1.0000
49.3000 29.0000 1.0000
49.3700 30.0000 1.0000
49.4400 19.0000 1.0000
49.5100 21.0000 1.0000
49.5800 24.0000 1.0000
49.6500 16.0000 1.0000
49.7200 17.0000 1.0000
49.7900 17.0000 1.0000
49.8600 9.0000 1.0000
49.9300 11.0000 1.0000
50.0000 16.0000 1.0000
50.0700 9.0000 1.0000
50.1400 6.0000 1.0000
50.2100 8.0000 1.0000
50.2800 9.0000 1.0000
50.3500 8.0000 1.0000
50.4200 8.0000 1.0000
50.4900 9.0000 1.0000
50.5600 10.0000 1.0000
50.6300 16.0000 1.0000
50.7000 8.0000 1.0000
50.7700 7.0000 1.0000
50.8400 9.0000 1.0000
50.9100 11.0000 1.0000
50.9800 5.0000 1.0000
51.0500 5.0000 1.0000
51.1200 2.0000 1.0000
51.1900 10.0000 1.0000
51.2600 6.0000 1.0000
51.3300 9.0000 1.0000
51.4000 7.0000 1.0000
51.4700 13.0000 1.0000
51.5400 5.0000 1.0000
51.6100 6.0000 1.0000
51.6800 7.0000 1.0000
51.7500 3.0000 1.0000
51.8200 8.0000 1.0000
51.8900 13.0000 1.0000
51.9600 4.0000 1.0000
52.0300 10.0000 1.0000
52.1000 6.0000 1.0000
52.1700 14.0000 1.0000
52.2400 9.0000 1.0000
52.3100 6.0000 1.0000
52.3800 4.0000 1.0000
52.4500 13.0000 1.0000
52.5200 7.0000 1.0000
52.5900 10.0000 1.0000
52.6600 7.0000 1.0000
52.7300 7.0000 1.0000
52.8000 10.0000 1.0000
52.8700 7.0000 1.0000
52.9400 7.0000 1.0000
53.0100 2.0000 1.0000
53.0800 6.0000 1.0000
53.1500 4.0000 1.0000
53.2200 10.0000 1.0000
53.2900 9.0000 1.0000
53.3600 4.0000 1.0000
53.4300 7.0000 1.0000
53.5000 13.0000 1.0000
53.5700 8.0000 1.0000
53.6400 5.0000 1.0000
53.7100 5.0000 1.0000
53.7800 6.0000 1.0000
53.8500 5.0000 1.0000
53.9200 11.0000 1.0000
53.9900 5.0000 1.0000
54.0600 12.0000 1.0000
54.1300 8.0000 1.0000
54.2000 9.0000 1.0000
54.2700 11.0000 1.0000
54.3400 13.0000 1.0000
54.4100 8.0000 1.0000
54.4800 3.0000 1.0000
54.5500 7.0000 1.0000
54.6200 3.0000 1.0000
54.6900 3.0000 1.0000
54.7600 6.0000 1.0000
54.8300 7.0000 1.0000
54.9000 10.0000 1.0000
54.9700 3.0000 1.0000
55.0400 5.0000 1.0000
55.1100 13.0000 1.0000
55.1800 5.0000 1.0000
55.2500 1.0000 1.0000
55.3200 7.0000 1.0000
55.3900 4.0000 1.0000
55.4600 9.0000 1.0000
55.5300 7.0000 1.0000
55.6000 8.0000 1.0000
55.6700 6.0000 1.0000
55.7400 10.0000 1.0000
55.8100 6.0000 1.0000
55.8800 6.0000 1.0000
55.9500 7.0000 1.0000
56.0200 6.0000 1.0000
56.0900 8.0000 1.0000
56.1600 6.0000 1.0000
56.2300 9.0000 1.0000
56.3000 4.0000 1.0000
56.3700 12.0000 1.0000
56.4400 6.0000 1.0000
56.5100 7.0000 1.0000
56.5800 6.0000 1.0000
56.6500 5.0000 1.0000
56.7200 6.0000 1.0000
56.7900 5.0000 1.0000
56.8600 8.0000 1.0000
56.9300 12.0000 1.0000
57.0000 3.0000 1.0000
57.0700 9.0000 1.0000
57.1400 6.0000 1.0000
57.2100 6.0000 1.0000
57.2800 6.0000 1.0000
57.3500 4.0000 1.0000
57.4200 7.0000 1.0000
57.4900 11.0000 1.0000
57.5600 8.0000 1.0000
57.6300 5.0000 1.0000
57.7000 1.0000 1.0000
57.7700 13.0000 1.0000
57.8400 8.0000 1.0000
57.9100 10.0000 1.0000
57.9800 5.0000 1.0000
58.0500 8.0000 1.0000
58.1200 4.0000 1.0000
58.1900 8.0000 1.0000
58.2600 8.0000 1.0000
58.3300 9.0000 1.0000
58.4000 4.0000 1.0000
58.4700 7.0000 1.0000
58.5400 13.0000 1.0000
58.6100 9.0000 1.0000
58.6800 12.0000 1.0000
58.7500 3.0000 1.0000
58.8200 7.0000 1.0000
58.8900 11.0000 1.0000
58.9600 6.0000 1.0000
59.0300 4.0000 1.0000
59.1000 6.0000 1.0000
59.1700 9.0000 1.0000
59.2400 9.0000 1.0000
59.3100 5.0000 1.0000
59.3800 6.0000 1.0000
59.4500 6.0000 1.0000
59.5200 7.0000 1.0000
59.5900 7.0000 1.0000
59.6600 6.0000 1.0000
59.7300 10.0000 1.0000
59.8000 4.0000 1.0000
59.8700 10.0000 1.0000
59.9400 5.0000 1.0000
60.0100 6.0000 1.0000
60.0800 9.0000 1.0000
60.1500 5.0000 1.0000
60.2200 4.0000 1.0000
60.2900 11.0000 1.0000
60.3600 6.0000 1.0000
60.4300 6.0000 1.0000
60.5000 8.0000 1.0000
60.5700 6.0000 1.0000
60.6400 6.0000 1.0000
60.7100 8.0000 1.0000
60.7800 2.0000 1.0000
60.8500 4.0000 1.0000
60.9200 4.0000 1.0000
60.9900 7.0000 1.0000
61.0600 4.0000 1.0000
61.1300 7.0000 1.0000
61.2000 10.0000 1.0000
61.2700 5.0000 1.0000
61.3400 9.0000 1.0000
61.4100 8.0000 1.0000
61.4800 7.0000 1.0000
61.5500 2.0000 1.0000
61.6200 8.0000 1.0000
61.6900 6.0000 1.0000
61.7600 16.0000 1.0000
61.8300 10.0000 1.0000
61.9000 9.0000 1.0000
61.9700 13.0000 1.0000
62.0400 9.0000 1.0000
62.1100 9.0000 1.0000
62.1800 13.0000 1.0000
62.2500 6.0000 1.0000
62.3200 9.0000 1.0000
62.3900 6.0000 1.0000
62.4600 9.0000 1.0000
62.5300 5.0000 1.0000
62.6000 12.0000 1.0000
62.6700 4.0000 1.0000
62.7400 6.0000 1.0000
62.8100 6.0000 1.0000
62.8800 8.0000 1.0000
62.9500 7.0000 1.0000
63.0200 8.0000 1.0000
63.0900 9.0000 1.0000
63.1600 11.0000 1.0000
63.2300 7.0000 1.0000
63.3000 6.0000 1.0000
63.3700 10.0000 1.0000
63.4400 6.0000 1.0000
63.5100 6.0000 1.0000
63.5800 5.0000 1.0000
63.6500 10.0000 1.0000
63.7200 4.0000 1.0000
63.7900 5.0000 1.0000
63.8600 14.0000 1.0000
63.9300 9.0000 1.0000
64.0000 11.0000 1.0000
64.0700 10.0000 1.0000
64.1400 7.0000 1.0000
64.2100 10.0000 1.0000
64.2800 11.0000 1.0000
64.3500 3.0000 1.0000
64.4200 11.0000 1.0000
64.4900 5.0000 1.0000
64.5600 9.0000 1.0000
64.6300 10.0000 1.0000
64.7000 8.0000 1.0000
64.7700 10.0000 1.0000
64.8400 15.0000 1.0000
64.9100 5.0000 1.0000
64.9800 14.0000 1.0000
65.0500 8.0000 1.0000
65.1200 16.0000 1.0000
65.1900 10.0000 1.0000
65.2600 14.0000 1.0000
65.3300 16.0000 1.0000
65.4000 11.0000 1.0000
65.4700 7.0000 1.0000
65.5400 9.0000 1.0000
65.6100 8.0000 1.0000
65.6800 6.0000 1.0000
65.7500 9.0000 1.0000
65.8200 6.0000 1.0000
65.8900 8.0000 1.0000
65.9600 8.0000 1.0000
66.0300 11.0000 1.0000
66.1000 12.0000 1.0000
66.1700 12.0000 1.0000
66.2400 16.0000 1.0000
66.3100 14.0000 1.0000
66.3800 13.0000 1.0000
66.4500 17.0000 1.0000
66.5200 8.0000 1.0000
66.5900 13.0000 1.0000
66.6600 11.0000 1.0000
66.7300 18.0000 1.0000
66.8000 12.0000 1.0000
66.8700 17.0000 1.0000
66.9400 19.0000 1.0000
67.0100 22.0000 1.0000
67.0800 15.0000 1.0000
67.1500 15.0000 1.0000
67.2200 23.0000 1.0000
67.2900 33.0000 1.0000
67.3600 9.0000 1.0000
67.4300 26.0000 1.0000
67.5000 26.0000 1.0000
67.5700 21.0000 1.0000
67.6400 20.0000 1.0000
67.7100 28.0000 1.0000
67.7800 39.0000 1.0000
67.8500 32.0000 1.0000
67.9200 39.0000 1.0000
67.9900 60.0000 1.0000
68.0600 55.0000 1.0000
68.1300 66.0000 1.0000
68.2000 88.0000 1.0000
68.2700 99.0000 1.0000
68.3400 110.0000 1.0000
68.4100 135.0000 1.0000
68.4800 189.0000 1.0000
68.5500 246.0000 1.0000
68.6200 344.0000 1.0000
68.6900 464.0000 1.0000
68.7600 775.0000 1.0000
68.8300 1197.0000 1.0000
68.9000 1716.0000 1.0000
68.9700 3105.0000 1.0000
69.0400 5436.0000 1.0000
69.1100 8214.0000 1.0000
69.1800 9479.0000 1.0000
69.2500 8367.0000 1.0000
69.3200 5630.0000 1.0000
69.3900 3135.0000 1.0000
69.4600 1765.0000 1.0000
69.5300 1193.0000 1.0000
69.6000 811.0000 1.0000
69.6700 509.0000 1.0000
69.7400 373.0000 1.0000
69.8100 289.0000 1.0000
69.8800 229.0000 1.0000
69.9500 177.0000 1.0000
70.0200 140.0000 1.0000
70.0900 130.0000 1.0000
70.1600 112.0000 1.0000
70.2300 93.0000 1.0000
70.3000 99.0000 1.0000
70.3700 67.0000 1.0000
70.4400 54.0000 1.0000
70.5100 51.0000 1.0000
70.5800 51.0000 1.0000
70.6500 42.0000 1.0000
70.7200 30.0000 1.0000
70.7900 25.0000 1.0000
70.8600 30.0000 1.0000
70.9300 25.0000 1.0000
71.0000 27.0000 1.0000
71.0700 13.0000 1.0000
71.1400 26.0000 1.0000
71.2100 22.0000 1.0000
71.2800 17.0000 1.0000
71.3500 25.0000 1.0000
71.4200 25.0000 1.0000
71.4900 20.0000 1.0000
71.5600 25.0000 1.0000
71.6300 27.0000 1.0000
71.7000 18.0000 1.0000
71.7700 17.0000 1.0000
71.8400 21.0000 1.0000
71.9100 25.0000 1.0000
71.9800 32.0000 1.0000
72.0500 22.0000 1.0000
72.1200 18.0000 1.0000
72.1900 29.0000 1.0000
72.2600 30.0000 1.0000
72.3300 29.0000 1.0000
72.4000 69.0000 1.0000
72.4700 315.0000 1.0000
72.5400 4347.0000 1.0000
72.6100 88926.0000 1.0000
72.6800 5908.0000 1.0000
72.7500 194.0000 1.0000
72.8200 113.0000 1.0000
72.8900 86.0000 1.0000
72.9600 80.0000 1.0000
73.0300 76.0000 1.0000
73.1000 68.0000 1.0000
73.1700 59.0000 1.0000
73.2400 70.0000 1.0000
73.3100 79.0000 1.0000
73.3800 64.0000 1.0000
73.4500 68.0000 1.0000
73.5200 55.0000 1.0000
73.5900 69.0000 1.0000
73.6600 74.0000 1.0000
73.7300 59.0000 1.0000
73.8000 47.0000 1.0000
73.8700 56.0000 1.0000
73.9400 51.0000 1.0000
74.0100 45.0000 1.0000
74.0800 35.0000 1.0000
74.1500 41.0000 1.0000
74.2200 33.0000 1.0000
74.2900 22.0000 1.0000
74.3600 35.0000 1.0000
74.4300 17.0000 1.0000
74.5000 26.0000 1.0000
74.5700 21.0000 1.0000
74.6400 8.0000 1.0000
74.7100 18.0000 1.0000
74.7800 17.0000 1.0000
74.8500 5.0000 1.0000
74.9200 12.0000 1.0000
74.9900 9.0000 1.0000
75.0600 8.0000 1.0000
75.1300 11.0000 1.0000
75.2000 8.0000 1.0000
75.2700 3.0000 1.0000
75.3400 10.0000 1.0000
75.4100 2.0000 1.0000
75.4800 8.0000 1.0000
75.5500 8.0000 1.0000
75.6200 5.0000 1.0000
75.6900 5.0000 1.0000
75.7600 11.0000 1.0000
75.8300 6.0000 1.0000
75.9000 7.0000 1.0000
75.9700 6.0000 1.0000
76.0400 14.0000 1.0000
76.1100 10.0000 1.0000
76.1800 13.0000 1.0000
76.2500 6.0000 1.0000
76.3200 8.0000 1.0000
76.3900 7.0000 1.0000
76.4600 6.0000 1.0000
76.5300 8.0000 1.0000
76.6000 10.0000 1.0000
76.6700 11.0000 1.0000
76.7400 7.0000 1.0000
76.8100 5.0000 1.0000
76.8800 11.0000 1.0000
76.9500 6.0000 1.0000
77.0200 5.0000 1.0000
77.0900 8.0000 1.0000
77.1600 8.0000 1.0000
77.2300 6.0000 1.0000
77.3000 5.0000 1.0000
77.3700 5.0000 1.0000
77.4400 8.0000 1.0000
77.5100 6.0000 1.0000
77.5800 6.0000 1.0000
77.6500 6.0000 1.0000
77.7200 7.0000 1.0000
77.7900 13.0000 1.0000
77.8600 10.0000 1.0000
77.9300 2.0000 1.0000
78.0000 4.0000 1.0000
78.0700 3.0000 1.0000
78.1400 3.0000 1.0000
78.2100 8.0000 1.0000
78.2800 7.0000 1.0000
78.3500 5.0000 1.0000
78.4200 6.0000 1.0000
78.4900 3.0000 1.0000
78.5600 7.0000 1.0000
78.6300 2.0000 1.0000
78.7000 2.0000 1.0000
78.7700 5.0000 1.0000
78.8400 12.0000 1.0000
78.9100 9.0000 1.0000
78.9800 6.0000 1.0000
79.0500 6.0000 1.0000
79.1200 6.0000 1.0000
79.1900 7.0000 1.0000
79.2600 12.0000 1.0000
79.3300 11.0000 1.0000
79.4000 10.0000 1.0000
79.4700 8.0000 1.0000
79.5400 8.0000 1.0000
79.6100 8.0000 1.0000
79.6800 4.0000 1.0000
79.7500 10.0000 1.0000
79.8200 7.0000 1.0000
79.8900 5.0000 1.0000
79.9600 6.0000 1.0000
80.0300 8.0000 1.0000
80.1000 9.0000 1.0000
80.1700 11.0000 1.0000
80.2400 6.0000 1.0000
80.3100 6.0000 1.0000
80.3800 5.0000 1.0000
80.4500 7.0000 1.0000
80.5200 12.0000 1.0000
80.5900 8.0000 1.0000
80.6600 7.0000 1.0000
80.7300 5.0000 1.0000
80.8000 8.0000 1.0000
80.8700 5.0000 1.0000
80.9400 9.0000 1.0000
81.0100 7.0000 1.0000
81.0800 7.0000 1.0000
81.1500 7.0000 1.0000
81.2200 9.0000 1.0000
81.2900 3.0000 1.0000
81.3600 2.0000 1.0000
81.4300 4.0000 1.0000
81.5000 9.0000 1.0000
81.5700 7.0000 1.0000
81.6400 11.0000 1.0000
81.7100 4.0000 1.0000
81.7800 6.0000 1.0000
81.8500 6.0000 1.0000
81.9200 10.0000 1.0000
81.9900 5.0000 1.0000
82.0600 4.0000 1.0000
82.1300 9.0000 1.0000
82.2000 7.0000 1.0000
82.2700 10.0000 1.0000
82.3400 3.0000 1.0000
82.4100 6.0000 1.0000
82.4800 2.0000 1.0000
82.5500 4.0000 1.0000
82.6200 8.0000 1.0000
82.6900 11.0000 1.0000
82.7600 8.0000 1.0000
82.8300 6.0000 1.0000
82.9000 8.0000 1.0000
82.9700 10.0000 1.0000
83.0400 9.0000 1.0000
83.1100 7.0000 1.0000
83.1800 5.0000 1.0000
83.2500 2.0000 1.0000
83.3200 3.0000 1.0000
83.3900 7.0000 1.0000
83.4600 8.0000 1.0000
83.5300 7.0000 1.0000
83.6000 5.0000 1.0000
83.6700 7.0000 1.0000
83.7400 4.0000 1.0000
83.8100 6.0000 1.0000
83.8800 8.0000 1.0000
83.9500 9.0000 1.0000
84.0200 5.0000 1.0000
84.0900 9.0000 1.0000
84.1600 6.0000 1.0000
84.2300 6.0000 1.0000
84.3000 6.0000 1.0000
84.3700 6.0000 1.0000
84.4400 3.0000 1.0000
84.5100 10.0000 1.0000
84.5800 8.0000 1.0000
84.6500 3.0000 1.0000
84.7200 9.0000 1.0000
84.7900 6.0000 1.0000
84.8600 7.0000 1.0000
84.9300 8.0000 1.0000
85.0000 8.0000 1.0000
85.0700 6.0000 1.0000
85.1400 6.0000 1.0000
85.2100 7.0000 1.0000
85.2800 5.0000 1.0000
85.3500 7.0000 1.0000
85.4200 8.0000 1.0000
85.4900 6.0000 1.0000
85.5600 7.0000 1.0000
85.6300 4.0000 1.0000
85.7000 6.0000 1.0000
85.7700 6.0000 1.0000
85.8400 9.0000 1.0000
85.9100 7.0000 1.0000
85.9800 1.0000 1.0000
86.0500 2.0000 1.0000
86.1200 3.0000 1.0000
86.1900 7.0000 1.0000
86.2600 5.0000 1.0000
86.3300 6.0000 1.0000
86.4000 7.0000 1.0000
86.4700 6.0000 1.0000
86.5400 11.0000 1.0000
86.6100 5.0000 1.0000
86.6800 4.0000 1.0000
86.7500 6.0000 1.0000
86.8200 8.0000 1.0000
86.8900 7.0000 1.0000
86.9600 7.0000 1.0000
87.0300 3.0000 1.0000
87.1000 16.0000 1.0000
87.1700 5.0000 1.0000
87.2400 7.0000 1.0000
87.3100 1.0000 1.0000
87.3800 7.0000 1.0000
87.4500 2.0000 1.0000
87.5200 5.0000 1.0000
87.5900 5.0000 1.0000
87.6600 9.0000 1.0000
87.7300 10.0000 1.0000
87.8000 8.0000 1.0000
87.8700 6.0000 1.0000
87.9400 5.0000 1.0000
88.0100 4.0000 1.0000
88.0800 4.0000 1.0000
88.1500 3.0000 1.0000
88.2200 7.0000 1.0000
88.2900 9.0000 1.0000
88.3600 3.0000 1.0000
88.4300 6.0000 1.0000
88.5000 6.0000 1.0000
88.5700 6.0000 1.0000
88.6400 6.0000 1.0000
88.7100 9.0000 1.0000
88.7800 6.0000 1.0000
88.8500 6.0000 1.0000
88.9200 5.0000 1.0000
88.9900 9.0000 1.0000
89.0600 8.0000 1.0000
89.1300 6.0000 1.0000
89.2000 5.0000 1.0000
89.2700 7.0000 1.0000
89.3400 4.0000 1.0000
89.4100 8.0000 1.0000
89.4800 8.0000 1.0000
89.5500 11.0000 1.0000
89.6200 6.0000 1.0000
89.6900 5.0000 1.0000
89.7600 8.0000 1.0000
89.8300 7.0000 1.0000
89.9000 10.0000 1.0000
89.9700 1.0000 1.0000
90.0400 5.0000 1.0000
90.1100 6.0000 1.0000
90.1800 2.0000 1.0000
90.2500 6.0000 1.0000
90.3200 6.0000 1.0000
90.3900 5.0000 1.0000
90.4600 10.0000 1.0000
90.5300 11.0000 1.0000
90.6000 3.0000 1.0000
90.6700 5.0000 1.0000
90.7400 9.0000 1.0000
90.8100 6.0000 1.0000
90.8800 6.0000 1.0000
90.9500 5.0000 1.0000
91.0200 9.0000 1.0000
91.0900 7.0000 1.0000
91.1600 6.0000 1.0000
91.2300 11.0000 1.0000
91.3000 8.0000 1.0000
91.3700 11.0000 1.0000
91.4400 4.0000 1.0000
91.5100 3.0000 1.0000
91.5800 4.0000 1.0000
91.6500 11.0000 1.0000
91.7200 8.0000 1.0000
91.7900 7.0000 1.0000
91.8600 8.0000 1.0000
91.9300 4.0000 1.0000
92.0000 9.0000 1.0000
92.0700 4.0000 1.0000
92.1400 11.0000 1.0000
92.2100 5.0000 1.0000
92.2800 3.0000 1.0000
92.3500 8.0000 1.0000
92.4200 7.0000 1.0000
92.4900 11.0000 1.0000
92.5600 7.0000 1.0000
92.6300 5.0000 1.0000
92.7000 9.0000 1.0000
92.7700 7.0000 1.0000
92.8400 8.0000 1.0000
92.9100 6.0000 1.0000
92.9800 10.0000 1.0000
93.0500 5.0000 1.0000
93.1200 10.0000 1.0000
93.1900 2.0000 1.0000
93.2600 5.0000 1.0000
93.3300 7.0000 1.0000
93.4000 5.0000 1.0000
93.4700 15.0000 1.0000
93.5400 6.0000 1.0000
93.6100 9.0000 1.0000
93.6800 9.0000 1.0000
93.7500 4.0000 1.0000
93.8200 5.0000 1.0000
93.8900 11.0000 1.0000
93.9600 8.0000 1.0000
94.0300 10.0000 1.0000
94.1000 9.0000 1.0000
94.1700 3.0000 1.0000
94.2400 10.0000 1.0000
94.3100 12.0000 1.0000
94.3800 11.0000 1.0000
94.4500 8.0000 1.0000
94.5200 9.0000 1.0000
94.5900 8.0000 1.0000
94.6600 8.0000 1.0000
94.7300 11.0000 1.0000
94.8000 9.0000 1.0000
94.8700 2.0000 1.0000
94.9400 11.0000 1.0000
95.0100 11.0000 1.0000
95.0800 10.0000 1.0000
95.1500 13.0000 1.0000
95.2200 11.0000 1.0000
95.2900 7.0000 1.0000
95.3600 15.0000 1.0000
95.4300 3.0000 1.0000
95.5000 8.0000 1.0000
95.5700 10.0000 1.0000
95.6400 5.0000 1.0000
95.7100 10.0000 1.0000
95.7800 8.0000 1.0000
95.8500 14.0000 1.0000
95.9200 8.0000 1.0000
95.9900 6.0000 1.0000
96.0600 9.0000 1.0000
96.1300 16.0000 1.0000
96.2000 18.0000 1.0000
96.2700 17.0000 1.0000
96.3400 12.0000 1.0000
96.4100 19.0000 1.0000
96.4800 13.0000 1.0000
96.5500 16.0000 1.0000
96.6200 11.0000 1.0000
96.6900 12.0000 1.0000
96.7600 33.0000 1.0000
96.8300 27.0000 1.0000
96.9000 22.0000 1.0000
96.9700 21.0000 1.0000
97.0400 26.0000 1.0000
97.1100 37.0000 1.0000
97.1800 54.0000 1.0000
97.2500 55.0000 1.0000
97.3200 39.0000 1.0000
97.3900 75.0000 1.0000
97.4600 88.0000 1.0000
97.5300 112.0000 1.0000
97.6000 117.0000 1.0000
97.6700 159.0000 1.0000
97.7400 200.0000 1.0000
97.8100 288.0000 1.0000
97.8800 436.0000 1.0000
97.9500 569.0000 1.0000
98.0200 701.0000 1.0000
98.0900 1008.0000 1.0000
98.1600 1321.0000 1.0000
98.2300 1805.0000 1.0000
98.3000 2243.0000 1.0000
98.3700 2685.0000 1.0000
98.4400 2434.0000 1.0000
98.5100 2270.0000 1.0000
98.5800 1700.0000 1.0000
98.6500 1205.0000 1.0000
98.7200 851.0000 1.0000
98.7900 584.0000 1.0000
98.8600 468.0000 1.0000
98.9300 408.0000 1.0000
99.0000 294.0000 1.0000
99.0700 220.0000 1.0000
99.1400 198.0000 1.0000
99.2100 149.0000 1.0000
99.2800 145.0000 1.0000
99.3500 98.0000 1.0000
99.4200 90.0000 1.0000
99.4900 72.0000 1.0000
99.5600 68.0000 1.0000
99.6300 62.0000 1.0000
99.7000 52.0000 1.0000
99.7700 51.0000 1.0000
99.8400 45.0000 1.0000
99.9100 31.0000 1.0000
99.9800 31.0000 1.0000
100.0500 29.0000 1.0000
100.1200 44.0000 1.0000
100.1900 29.0000 1.0000
100.2600 32.0000 1.0000
100.3300 20.0000 1.0000
100.4000 29.0000 1.0000
100.4700 30.0000 1.0000
100.5400 27.0000 1.0000
100.6100 28.0000 1.0000
100.6800 37.0000 1.0000
100.7500 24.0000 1.0000
100.8200 24.0000 1.0000
100.8900 30.0000 1.0000
100.9600 29.0000 1.0000
101.0300 24.0000 1.0000
101.1000 27.0000 1.0000
101.1700 27.0000 1.0000
101.2400 25.0000 1.0000
101.3100 21.0000 1.0000
101.3800 32.0000 1.0000
101.4500 29.0000 1.0000
101.5200 26.0000 1.0000
101.5900 28.0000 1.0000
101.6600 27.0000 1.0000
101.7300 31.0000 1.0000
101.8000 49.0000 1.0000
101.8700 35.0000 1.0000
101.9400 35.0000 1.0000
102.0100 27.0000 1.0000
102.0800 30.0000 1.0000
102.1500 27.0000 1.0000
102.2200 19.0000 1.0000
102.2900 27.0000 1.0000
102.3600 21.0000 1.0000
102.4300 18.0000 1.0000
102.5000 16.0000 1.0000
102.5700 25.0000 1.0000
102.6400 33.0000 1.0000
102.7100 29.0000 1.0000
102.7800 32.0000 1.0000
102.8500 42.0000 1.0000
102.9200 40.0000 1.0000
102.9900 43.0000 1.0000
103.0600 50.0000 1.0000
103.1300 58.0000 1.0000
103.2000 55.0000 1.0000
103.2700 64.0000 1.0000
103.3400 79.0000 1.0000
103.4100 93.0000 1.0000
103.4800 104.0000 1.0000
103.5500 136.0000 1.0000
103.6200 141.0000 1.0000
103.6900 178.0000 1.0000
103.7600 248.0000 1.0000
103.8300 319.0000 1.0000
103.9000 557.0000 1.0000
103.9700 1068.0000 1.0000
104.0400 3083.0000 1.0000
104.1100 14850.0000 1.0000
104.1800 10713.0000 43.9397
104.2500 17498.0000 43.9397
104.3200 60032.0000 1.0000
104.3900 8971.0000 1.0000
104.4600 28573.0000 1.0000
104.5300 2005.0000 1.0000
104.6000 669.0000 1.0000
104.6700 388.0000 1.0000
104.7400 294.0000 1.0000
104.8100 234.0000 1.0000
104.8800 247.0000 1.0000
104.9500 218.0000 1.0000
105.0200 204.0000 1.0000
105.0900 217.0000 1.0000
105.1600 214.0000 1.0000
105.2300 197.0000 1.0000
105.3000 159.0000 1.0000
105.3700 171.0000 1.0000
105.4400 163.0000 1.0000
105.5100 157.0000 1.0000
105.5800 168.0000 1.0000
105.6500 137.0000 1.0000
105.7200 160.0000 1.0000
105.7900 143.0000 1.0000
105.8600 126.0000 1.0000
105.9300 141.0000 1.0000
106.0000 133.0000 1.0000
106.0700 125.0000 1.0000
106.1400 135.0000 1.0000
106.2100 133.0000 1.0000
106.2800 120.0000 1.0000
106.3500 133.0000 1.0000
106.4200 105.0000 1.0000
106.4900 124.0000 1.0000
106.5600 101.0000 1.0000
106.6300 103.0000 1.0000
106.7000 107.0000 1.0000
106.7700 101.0000 1.0000
106.8400 83.0000 1.0000
106.9100 73.0000 1.0000
106.9800 65.0000 1.0000
107.0500 73.0000 1.0000
107.1200 56.0000 1.0000
107.1900 56.0000 1.0000
107.2600 52.0000 1.0000
107.3300 37.0000 1.0000
107.4000 47.0000 1.0000
107.4700 47.0000 1.0000
107.5400 26.0000 1.0000
107.6100 31.0000 1.0000
107.6800 32.0000 1.0000
107.7500 21.0000 1.0000
107.8200 29.0000 1.0000
107.8900 14.0000 1.0000
107.9600 16.0000 1.0000
108.0300 13.0000 1.0000
108.1000 11.0000 1.0000
108.1700 17.0000 1.0000
108.2400 16.0000 1.0000
108.3100 15.0000 1.0000
108.3800 13.0000 1.0000
108.4500 9.0000 1.0000
108.5200 12.0000 1.0000
108.5900 14.0000 1.0000
108.6600 10.0000 1.0000
108.7300 10.0000 1.0000
108.8000 9.0000 1.0000
108.8700 18.0000 1.0000
108.9400 18.0000 1.0000
109.0100 14.0000 1.0000
109.0800 13.0000 1.0000
109.1500 8.0000 1.0000
109.2200 6.0000 1.0000
109.2900 8.0000 1.0000
109.3600 11.0000 1.0000
109.4300 9.0000 1.0000
109.5000 12.0000 1.0000
109.5700 11.0000 1.0000
109.6400 16.0000 1.0000
109.7100 13.0000 1.0000
109.7800 9.0000 1.0000
109.8500 11.0000 1.0000
109.9200 13.0000 1.0000
109.9900 14.0000 1.0000
110.0600 11.0000 1.0000
110.1300 8.0000 1.0000
110.2000 8.0000 1.0000
110.2700 9.0000 1.0000
110.3400 6.0000 1.0000
110.4100 17.0000 1.0000
110.4800 7.0000 1.0000
110.5500 4.0000 1.0000
110.6200 9.0000 1.0000
110.6900 13.0000 1.0000
110.7600 5.0000 1.0000
110.8300 12.0000 1.0000
110.9000 9.0000 1.0000
110.9700 6.0000 1.0000
111.0400 7.0000 1.0000
111.1100 6.0000 1.0000
111.1800 3.0000 1.0000
111.2500 6.0000 1.0000
111.3200 8.0000 1.0000
111.3900 5.0000 1.0000
111.4600 6.0000 1.0000
111.5300 9.0000 1.0000
111.6000 9.0000 1.0000
111.6700 3.0000 1.0000
111.7400 9.0000 1.0000
111.8100 13.0000 1.0000
111.8800 2.0000 1.0000
111.9500 5.0000 1.0000
112.0200 6.0000 1.0000
112.0900 3.0000 1.0000
112.1600 7.0000 1.0000
112.2300 6.0000 1.0000
112.3000 13.0000 1.0000
112.3700 7.0000 1.0000
112.4400 13.0000 1.0000
112.5100 5.0000 1.0000
112.5800 7.0000 1.0000
112.6500 7.0000 1.0000
112.7200 7.0000 1.0000
112.7900 11.0000 1.0000
112.8600 11.0000 1.0000
112.9300 7.0000 1.0000
113.0000 11.0000 1.0000
113.0700 10.0000 1.0000
113.1400 10.0000 1.0000
113.2100 8.0000 1.0000
113.2800 7.0000 1.0000
113.3500 14.0000 1.0000
113.4200 7.0000 1.0000
113.4900 6.0000 1.0000
113.5600 7.0000 1.0000
113.6300 7.0000 1.0000
113.7000 6.0000 1.0000
113.7700 8.0000 1.0000
113.8400 9.0000 1.0000
113.9100 7.0000 1.0000
113.9800 10.0000 1.0000
114.0500 5.0000 1.0000
114.1200 8.0000 1.0000
114.1900 7.0000 1.0000
114.2600 7.0000 1.0000
114.3300 13.0000 1.0000
114.4000 10.0000 1.0000
114.4700 5.0000 1.0000
114.5400 3.0000 1.0000
114.6100 8.0000 1.0000
114.6800 6.0000 1.0000
114.7500 5.0000 1.0000
114.8200 7.0000 1.0000
114.8900 3.0000 1.0000
114.9600 11.0000 1.0000
115.0000 9.0000 1.0000
*RAS_INT_END
*RAS_DATA_END